Workbook

Sheet 01_Idv_sin_noboa
A1: encuesta_raw | B1: Encuestador | C1: ini_enc | D1: fin_enc | E1: Fecha | F1: Arauz | G1: Lasso | H1: Perez | I1: Montufar | J1: Pena | K1: Gutierrez | L1: Larrea | M1: Romero | N1: Velasco | O1: Celi | P1: Otros | Q1: Blancos | R1: Nulo | S1: NSNR | T1: diseno_enc
A2: Click Report Enero 2021 | B2: Click report | C2: 44227 | D2: 44227 | E2: =AVERAGE(C2:D2) -> 44227 | F2: 0.2375 | G2: 0.2247 | H2: 0.1317 | I2: 0.009 | J2: 0.0091 | K2: 0.021 | L2: 0.0027 | M2: 0.0151 | N2: 0.0091 | O2: 0.0072 | P2: 0.0178 | Q2: 0.0803 | R2: 0.2348 | T2: Muestreo aleatorio simple, entrevistas cara a cara en hogares, población mayores de 16 años registrados para votar en elecciones 2021, 2.280 encuestas, margen de error +/- 1.5%
A3: Mercanalisis SIN NOBOA 15/12 a 23/12 | B3: Mercanalisis | C3: 44180 | D3: 44188 | E3: =AVERAGE(C3:D3) -> 44184 | F3: 0.176 | G3: 0.172 | H3: 0.064 | I3: 0.006 | J3: 0.012 | K3: 0.028 | L3: 0.006 | M3: 0.021 | N3: 0.013 | O3: 0.012 | P3: 0.044 | Q3: 0.23 | R3: 0.216 | T3: Muestreo estratificado con afijación proporcional en base al peso electoral de cada provincia, 5.000 casos, margen de error +/-2%
A4: Perfiles de Opinión SIN NOBOA diciembre | B4: Perfiles de Opinión | C4: 44196 | D4: 44196 | E4: =AVERAGE(C4:D4) -> 44196 | F4: 0.2575 | G4: 0.1522 | H4: 0.1184 | I4: 0.0045 | J4: 0.0172 | K4: 0.0147 | L4: 0.0031 | M4: 0.011 | N4: 0.0046 | O4: 0.0039 | P4: 0.0088 | Q4: 0.0904 | R4: 0.3137 | T4: Entrevistas personales utilizando un cuestionario semi-estructurado, población de 18 a 65 años de edad residentes y votantes, 4.576 entrevistas, margen de error +/- 1.4%
A5: Estrategia Consultores al 23/12 | B5: Estrategia Consultores | C5: 44188 | D5: 44188 | E5: =AVERAGE(C5:D5) -> 44188 | F5: 0.223 | G5: 0.202 | H5: 0.174 | I5: 0.027 | K5: 0.021 | L5: 0.025 | M5: 0.043 | N5: 0.012 | P5: 0.098 | R5: 0.089 | S5: 0.086 | T5: Sin datos
A6: IESOP Inf. Confidencial 24/11 a 27/11 | B6: IESOP | C6: 44159 | D6: 44162 | E6: =AVERAGE(C6:D6) -> 44160.5 | F6: 0.21 | G6: 0.19 | H6: 0.12 | I6: 0.02 | K6: 0.01 | M6: 0.01 | P6: 0.03 | Q6: 0.09 | R6: 0.32 | T6: Muestra aleatoria, entrevistas telefónicas, población mayor de 16 años en zonas urbanas, 2.600 casos, margen de error +/-3.5%
A7: Clima Social 8/11 a 11/11 | B7: Clima Social | C7: 44143 | D7: 44146 | E7: =AVERAGE(C7:D7) -> 44144.5 | F7: 0.23 | G7: 0.2 | H7: 0.129 | I7: 0.008 | J7: 0.026 | K7: 0.039 | L7: 0.017 | M7: 0.024 | N7: 0.01 | O7: 0.007 | P7: 0.022 | Q7: 0.035 | R7: 0.112 | S7: 0.139 | T7: Mustra realizada a partir del padrón electoral, encuestas en hogar a personas mayores de 16 años habilitadas para votar en la parroquia donde son entrevistadas, 2.579 casos, margen de error +/-1.9%
A8: IESOP Inf. Confidencial 6/11 a 9/11 | B8: IESOP | C8: 44141 | D8: 44144 | E8: =AVERAGE(C8:D8) -> 44142.5 | F8: 0.216 | G8: 0.17 | H8: 0.135 | I8: 0.016 | J8: 0.003 | K8: 0.012 | L8: 0.004 | M8: 0.004 | N8: 0.017 | O8: 0.002 | P8: 0.002 | Q8: 0.151 | R8: 0.266 | S8: 0.001 | T8: Sin datos
A9: Comunicaliza octubre | B9: Comunicaliza | C9: 44135 | D9: 44135 | E9: =AVERAGE(C9:D9) -> 44135 | F9: 0.193 | G9: 0.177 | H9: 0.184 | J9: 0.032 | K9: 0.017 | M9: 0.016 | P9: 0.051 | R9: 0.164 | S9: 0.166 | T9: Sin datos
A10: Cedatos 16/10 | B10: Cedatos | C10: 44120 | D10: 44120 | E10: =AVERAGE(C10:D10) -> 44120 | F10: 0.197 | G10: 0.261 | H10: 0.131 | I10: 0.01 | J10: 0.01 | K10: 0.01 | L10: 0.01 | M10: 0.01 | N10: 0.01 | O10: 0.01 | Q10: 0.088 | R10: 0.249 | T10: Encuesta probabilística con sistema CATI a personas mayores de 16 años, 1.800 casos, margen de error +/-3.2%
A11: Omar Maluk octubre | B11: Omar Maluk | C11: 44135 | D11: 44135 | E11: =AVERAGE(C11:D11) -> 44135 | F11: 0.308 | G11: 0.238 | H11: 0.088 | I11: 0.028 | J11: 0.008 | K11: 0.022 | L11: 0.022 | M11: 0.024 | O11: 0.011 | P11: 0.021 | S11: 0.231 | T11: 2 enucuestas conjuntas: encuesta a) presencial, 2.000 casos y encuesta b) vía redes sociales, 4.435 casos. Total 6.435 casos, margen de error conjunto cercano al 4%
A12: Omar Simón octubre | B12: Omar Simon | C12: 44135 | D12: 44135 | E12: =AVERAGE(C12:D12) -> 44135 | F12: 0.249 | G12: 0.111 | H12: 0.153 | I12: 0.011 | J12: 0.018 | K12: 0.02 | L12: 0.002 | N12: 0.019 | O12: 0.005 | P12: 0.037 | Q12: 0.068 | R12: 0.213 | S12: 0.095 | T12: Sin datos (2500 casos)
A13: Clima Social 30/9 a 4/10 | B13: Clima Social | C13: 44104 | D13: 44108 | E13: =AVERAGE(C13:D13) -> 44106 | F13: 0.186 | G13: 0.215 | H13: 0.107 | I13: 0.017 | J13: 0.046 | K13: 0.03 | L13: 0.039 | M13: 0.017 | N13: 0.017 | O13: 0.018 | P13: 0.006 | Q13: 0.021 | R13: 0.12 | S13: 0.161 | T13: Mustra realizada a partir del padrón electoral, encuestas en hogar a personas mayores de 16 años habilitadas para votar en la parroquia donde son entrevistadas, 2.017 casos, margen de error +/-2.2%
A14: Pulso Ciudadano 15/9 a 18/9 | B14: Pulso Ciudadano | C14: 44089 | D14: 44092 | E14: =AVERAGE(C14:D14) -> 44090.5 | F14: 0.2105 | G14: 0.1912 | H14: 0.0617 | I14: 0.0602 | J14: 0.018 | K14: 0.0188 | L14: 0.0406 | M14: 0.0432 | O14: 0.0097 | P14: 0.025 | S14: 0.322 | T14: Muestra no probabilística, entrevistas estratificadas aproporcionalmente por género, edad y ciduad de residencia y luego ponderada por el peso real de dichas variables, selección en base al padrón electoral de las 3 principales ciudades el país (Quito, Guayaquil y Cuenca), entrevistas vía telefónica (CATI) a través de un panel representativo con cobertura nacional, 1.400 entrevistas, margen de error +/-2.9%
A15: Cedatos 10/9 a 14/9 | B15: Cedatos | C15: 44084 | D15: 44088 | E15: =AVERAGE(C15:D15) -> 44086 | F15: 0.123 | G15: 0.163 | H15: 0.055 | I15: 0.006 | J15: 0.008 | K15: 0.007 | M15: 0.005 | N15: 0.005 | O15: 0.005 | P15: 0.027 | Q15: 0.006 | R15: 0.272 | S15: 0.318 | T15: Entrevistas mensuales en promedio de 1.670 ecuatorianos en 14 ciudades, en capacidad de votar, sistema CATI, margen de error +/-3.5%
A16: Atlas Intel 8/9 a 14/9 | B16: Atlas Intel | C16: 44082 | D16: 44088 | E16: =AVERAGE(C16:D16) -> 44085 | F16: 0.459 | G16: 0.32 | H16: 0.043 | I16: 0.011 | J16: 0.002 | K16: 0.003 | L16: 0.003 | M16: 0.009 | N16: 0.002 | O16: 0.009 | P16: 0.032 | Q16: 0.061 | S16: 0.045 | T16: Muestreo Postestratificado, representativo de la población target. Se seleccionaron aleatoriamente entrevistados en todas las provincias de Ecuador. Las respuestas de la muestra final tienen pesos estimados con un algoritmo de raking para garantizar la representatividad en 5 variables clave: sexo, región, edad, ingresos y voto en las elecciones presidenciales de Ecuador de 2017, población adulta de Ecuador, 3.772 casos a través de selección aleatoria en la web, margen de error +/- 2%
A17: Eureknow 26/8 a 6/9 | B17: Eureknow | C17: 44069 | D17: 44080 | E17: =AVERAGE(C17:D17) -> 44074.5 | F17: 0.22 | G17: 0.231 | H17: 0.205 | I17: 0.099 | M17: 0.066 | P17: 0.107 | Q17: 0.072 | T17: Muestreo desde panel georreferenciado. Quito y Guayaquil como dominios autorepresentados y Resto país como dominio corepresentado, residentes en las regiones señaladas entre 18 y 65 años, encuestas online usand un cuestionario estructurado, 750 casos, margen de error +/- 3.6%

Sheet Idv CON NOBOA
A1: Elecciones presidenciales Ecuador, 7 de febrero de 2021
A2: Últimas encuestas
B3: Andrés Arauz | C3: Guillermo Lasso | D3: Yaku Pérez | E3: César Montúfar | F3: Ximena Peña | G3: Álvaro Noboa | H3: Lucio Gutiérrez | I3: Gustavo Larrea | J3: Isidro Romero | K3: Juan Velasco | L3: Guillermo Celi | M3: Otros | N3: Blanco | O3: Nulo | P3: Ns/Nc | Q3: TOTAL NO DEFINIDOS
A4: Click Report Enero 2021 | B4: 0.2266 | C4: 0.1881 | D4: 0.0956 | E4: 0.007 | F4: 0.0059 | G4: 0.1915 | H4: 0.0143 | I4: 0.002 | J4: 0.0063 | K4: 0.0065 | L4: 0.0008 | M4: 0.0126 | N4: 0.079 | O4: 0.1638 | Q4: =SUM(N4:P4) -> 0.2428 | R4: Muestreo aleatorio simple, entrevistas cara a cara en hogares, población mayores de 16 años registrados para votar en elecciones 2021, 2.280 encuestas, margen de error +/- 1.5%
A5: Atlas Intel 23/12 a 29/12 | B5: 0.344 | C5: 0.267 | D5: 0.082 | E5: 0.01 | F5: 0.016 | G5: 0.116 | H5: 0.009 | I5: 0.004 | J5: 0.008 | K5: 0.001 | L5: 0.002 | M5: 0.036 | N5: 0.035 | P5: 0.07 | Q5: =SUM(N5:P5) -> 0.105 | R5: Muestreo Postestratificado, representativo de la población target. Se seleccionaron aleatoriamente entrevistados en todas las provincias de Ecuador. Las respuestas de la muestra final tienen pesos estimados con un algoritmo de raking para garantizar la representatividad en 5 variables clave: sexo, región, edad, ingresos y voto en las elecciones presidenciales de Ecuador de 2017, población adulta de Ecuador, 3.125 casos a través de selección aleatoria en la web, margen de error +/- 2%
A6: Mercanalisis CON NOBOA 15/12 a 23/12 | B6: 0.16 | C6: 0.15 | D6: 0.06 | E6: 0.01 | F6: 0.01 | G6: 0.07 | H6: 0.03 | I6: 0.01 | J6: 0.02 | K6: 0.01 | L6: 0.01 | M6: 0.05 | N6: 0.2 | O6: 0.21 | Q6: =SUM(N6:P6) -> 0.41 | R6: Muestreo estratificado con afijación proporcional en base al peso electoral de cada provincia, 5.000 casos, margen de error +/-2%
A7: Omar Maluk 7/12 a 23/12 | B7: 0.2216 | C7: 0.1139 | D7: 0.0697 | E7: 0.0069 | F7: 0.0075 | G7: 0.288 | H7: 0.0294 | I7: 0.0063 | J7: 0.0175 | L7: 0.0039 | M7: 0.0045 | N7: 0.0348 | O7: 0.196 | Q7: =SUM(N7:P7) -> 0.2308 | R7: Presencial, 6.300 casos
A8: Perfiles de Opinión CON NOBOA 19/12 a 26/12 | B8: 0.2351 | C8: 0.1229 | D8: 0.0989 | E8: 0.0031 | F8: 0.0165 | G8: 0.1688 | H8: 0.0133 | I8: 0.0025 | J8: 0.0085 | K8: 0.0039 | L8: 0.0048 | M8: 0.0088 | N8: 0.07 | O8: 0.2428 | Q8: =SUM(N8:P8) -> 0.3128 | R8: Entrevistas personales utilizando un cuestionario semi-estructurado, población de 18 a 65 años de edad residentes y votantes, 4.576 entrevistas, margen de error +/- 1.4%
A9: Eureknow 14/12 a 22/12 | B9: 0.208 | C9: 0.2 | D9: 0.091 | E9: 0.041 | G9: 0.237 | J9: 0.044 | K9: 0.032 | M9: 0.065 | N9: 0.082 | Q9: =SUM(N9:P9) -> 0.082 | R9: Muestreo desde panel georreferenciado. Quito y Guayaquil como dominios autorepresentados y Resto país como dominio corepresentado, residentes en las regiones señaladas entre 18 y 65 años, encuestas online usand un cuestionario estructurado, 1.400 casos, margen de error +/- 2.6%
A10: Clima Social 12/12 a 15/12 | B10: 0.233 | C10: 0.139 | D10: 0.128 | E10: 0.013 | F10: 0.03 | G10: 0.108 | H10: 0.026 | I10: 0.012 | J10: 0.024 | K10: 0.012 | L10: 0.007 | M10: 0.052 | N10: 0.018 | O10: 0.068 | P10: 0.131 | Q10: =SUM(N10:P10) -> 0.217 | R10: Mustra realizada a partir del padrón electoral, encuestas en hogar a personas mayores de 16 años habilitadas para votar en la parroquia donde son entrevistadas, 3.500 casos, margen de error +/-1.8%
A11: Celag 25/11 a 13/12 | B11: 0.28 | C11: 0.104 | D11: 0.162 | F11: 0.009 | G11: 0.175 | H11: 0.008 | I11: 0.007 | J11: 0.011 | M11: 0.01 | N11: 0.103 | P11: 0.131 | Q11: =SUM(N11:P11) -> 0.234 | R11: Muestra probabilística estratificada por región, población mayor de 16 años, 3.000 entrevistas presenciales, margen de error +/-2.2%
A12: Omar Maluk 30/11 | B12: 0.2358 | C12: 0.0889 | D12: 0.0613 | E12: 0.018 | F12: 0.0248 | G12: 0.3182 | H12: 0.0141 | I12: 0.009 | J12: 0.0236 | L12: 0.013 | M12: 0.0307 | N12: 0.0598 | O12: 0.1027 | Q12: =SUM(N12:P12) -> 0.1625 | R12: Sin datos
A13: IESOP Inf. Confidencial 24/11 a 27/11 | B13: 0.2 | C13: 0.17 | D13: 0.12 | E13: 0.02 | G13: 0.12 | H13: 0.01 | J13: 0.01 | M13: 0.02 | O13: 0.27 | P13: 0.06 | Q13: =SUM(N13:P13) -> 0.33 | R13: Muestra aleatoria, entrevistas telefónicas, población mayor de 16 años en zonas urbanas, 2.600 casos, margen de error +/-3.5%
A14: Cedatos 15/11 | B14: 0.111 | C14: 0.181 | D14: 0.062 | E14: 0.004 | F14: 0.002 | G14: 0.073 | H14: 0.003 | I14: 0.001 | J14: 0.005 | K14: 0.001 | L14: 0.002 | N14: 0.034 | O14: 0.286 | P14: 0.235 | Q14: =SUM(N14:P14) -> 0.555 | R14: Entrevistas mensuales en promedio de 1.670 ecuatorianos en 14 ciudades, en capacidad de votar, sistema CATI, margen de error +/-3.5%
A15: Promedio | B15: =AVERAGE(B4:B14) -> 0.22319091 | C15: =AVERAGE(C4:C14) -> 0.1568 | D15: =AVERAGE(D4:D14) -> 0.093681818 | E15: =AVERAGE(E4:E14) -> 0.0133 | F15: =AVERAGE(F4:F14) -> 0.013522222 | G15: =AVERAGE(G4:G14) -> 0.16959091 | H15: =AVERAGE(H4:H14) -> 0.01571 | I15: =AVERAGE(I4:I14) -> 0.0059777778 | ... Q15: =AVERAGE(Q4:Q14) -> 0.26199091

Sheet Votos válidos CON NOBOA
A1: Elecciones presidenciales Ecuador, 7 de febrero de 2021
A2: Últimas encuestas (proyección sobre voto válido)
B3: Andrés Arauz | C3: Guillermo Lasso | D3: Yaku Pérez | E3: Álvaro Noboa | F3: César Montúfar | G3: Ximena Peña | H3: Lucio Gutiérrez | I3: Gustavo Larrea | J3: Isidro Romero | K3: Juan Velasco | L3: Guillermo Celi | M3: Otros
A4: Click Report Enero 2021 | B4: ='Idv CON NOBOA'!B4/75.72% -> 0.29926043 | C4: ='Idv CON NOBOA'!C4/75.72% -> 0.24841521 | D4: ='Idv CON NOBOA'!D4/75.72% -> 0.12625462 | E4: ='Idv CON NOBOA'!G4/75.72% -> 0.25290544 | F4: ='Idv CON NOBOA'!E4/75.72% -> 0.0092445853 | G4: ='Idv CON NOBOA'!F4/75.72% -> 0.0077918648 | H4: ='Idv CON NOBOA'!H4/75.72% -> 0.018885367 | I4: ='Idv CON NOBOA'!I4/75.72% -> 0.0026413101 | J4: ='Idv CON NOBOA'!J4/75.72% -> 0.0083201268 | K4: ='Idv CON NOBOA'!K4/75.72% -> 0.0085842578 | L4: ='Idv CON NOBOA'!L4/75.72% -> 0.001056524 | M4: ='Idv CON NOBOA'!M4/75.72% -> 0.016640254 | N4: =SUM(F4:M4) -> 0.073164289 | O4: =SUM(B4:M4) -> 1
A5: Mercanalisis CON NOBOA 15/12 a 23/12 | B5: ='Idv CON NOBOA'!B5/0.59 -> 0.58305085 | C5: ='Idv CON NOBOA'!C5/0.59 -> 0.45254237 | D5: ='Idv CON NOBOA'!D5/0.59 -> 0.13898305 | E5: ='Idv CON NOBOA'!G5/0.59 -> 0.19661017 | F5: ='Idv CON NOBOA'!E5/0.59 -> 0.016949153 | G5: ='Idv CON NOBOA'!F5/0.59 -> 0.027118644 | H5: ='Idv CON NOBOA'!H5/0.59 -> 0.015254237 | I5: ='Idv CON NOBOA'!I5/0.59 -> 0.006779661 | J5: ='Idv CON NOBOA'!J5/0.59 -> 0.013559322 | K5: ='Idv CON NOBOA'!K5/0.59 -> 0.0016949153 | L5: ='Idv CON NOBOA'!L5/0.59 -> 0.0033898305 | M5: ='Idv CON NOBOA'!M5/0.59 -> 0.061016949 | N5: =SUM(F5:M5) -> 0.14576271 | O5: =SUM(B5:M5) -> 1.5169492
A6: Omar Maluk 7/12 a 23/12 | B6: ='Idv CON NOBOA'!B6/0.7692 -> 0.20800832 | C6: ='Idv CON NOBOA'!C6/0.7692 -> 0.1950078 | D6: ='Idv CON NOBOA'!D6/0.7692 -> 0.07800312 | E6: ='Idv CON NOBOA'!G6/0.7692 -> 0.09100364 | F6: ='Idv CON NOBOA'!E6/0.7692 -> 0.01300052 | G6: ='Idv CON NOBOA'!F6/0.7692 -> 0.01300052 | H6: ='Idv CON NOBOA'!H6/0.7692 -> 0.03900156 | I6: ='Idv CON NOBOA'!I6/0.7692 -> 0.01300052 | J6: ='Idv CON NOBOA'!J6/0.7692 -> 0.02600104 | K6: ='Idv CON NOBOA'!K6/0.7692 -> 0.01300052 | L6: ='Idv CON NOBOA'!L6/0.7692 -> 0.01300052 | M6: ='Idv CON NOBOA'!M6/0.7692 -> 0.0650026 | N6: =SUM(F6:M6) -> 0.1950078 | O6: =SUM(B6:M6) -> 0.76703068
A7: Perfiles de Opinión CON NOBOA 12/2020 | B7: ='Idv CON NOBOA'!B7/0.6872 -> 0.32246799 | C7: ='Idv CON NOBOA'!C7/0.6872 -> 0.16574505 | D7: ='Idv CON NOBOA'!D7/0.6872 -> 0.10142608 | E7: ='Idv CON NOBOA'!G7/0.6872 -> 0.41909197 | F7: ='Idv CON NOBOA'!E7/0.6872 -> 0.010040745 | G7: ='Idv CON NOBOA'!F7/0.6872 -> 0.010913853 | H7: ='Idv CON NOBOA'!H7/0.6872 -> 0.042782305 | I7: ='Idv CON NOBOA'!I7/0.6872 -> 0.0091676368 | J7: ='Idv CON NOBOA'!J7/0.6872 -> 0.025465658 | K7: ='Idv CON NOBOA'!K7/0.6872 -> 0 | L7: ='Idv CON NOBOA'!L7/0.6872 -> 0.0056752037 | M7: ='Idv CON NOBOA'!M7/0.6872 -> 0.006548312 | N7: =SUM(F7:M7) -> 0.11059371 | O7: =SUM(B7:M7) -> 1.1193248
A8: Atlas Intel 23/12 a 29/12 | B8: =B18/89.5% -> 0.38435754 | C8: =C18/89.5% -> 0.29832402 | D8: =D18/89.5% -> 0.091620112 | E8: =H18/89.5% -> 0.12960894 | F8: =F18/89.5% -> 0.011173184 | G8: =G18/89.5% -> 0.017877095 | H8: =I18/89.5% -> 0.010055866 | I8: =J18/89.5% -> 0.0044692737 | J8: =K18/89.5% -> 0.0089385475 | K8: =L18/89.5% -> 0.0011173184 | L8: =M18/89.5% -> 0.0022346369 | M8: =N18/89.5% -> 0.040223464 | N8: =SUM(F8:M8) -> 0.096089385 | O8: =SUM(B8:M8) -> 1
A9: Eureknow 14/12 a 22/12 | B9: =B20/91.8% -> 0.22657952 | C9: =C20/91.8% -> 0.21786492 | D9: =D20/91.8% -> 0.09912854 | E9: =H20/91.8% -> 0.25816993 | F9: =F20/91.8% -> 0.044662309 | J9: =K20/91.8% -> 0.047930283 | K9: =L20/91.8% -> 0.034858388 | L9: =M20/91.8% -> 0 | M9: =N20/91.8% -> 0.0708061 | N9: =SUM(F9:M9) -> 0.19825708 | O9: =SUM(B9:M9) -> 1
A10: Clima Social 12/12 a 15/12 | B10: =B21/78.3% -> 0.29757344 | C10: =C21/78.3% -> 0.17752235 | D10: =D21/78.3% -> 0.16347382 | E10: =H21/78.3% -> 0.13793103 | F10: =F21/78.3% -> 0.01660281 | G10: =G21/78.3% -> 0.038314176 | H10: =I21/78.3% -> 0.033205619 | I10: =J21/78.3% -> 0.01532567 | J10: =K21/78.3% -> 0.030651341 | K10: =L21/78.3% -> 0.01532567 | L10: =M21/78.3% -> 0.0089399745 | M10: =N21/78.3% -> 0.066411239 | N10: =SUM(F10:M10) -> 0.2247765 | O10: =SUM(B10:M10) -> 1.0012771
A11: Celag 25/11 a 13/12 | B11: =B22/76.6% -> 0.36553525 | C11: =C22/76.6% -> 0.13577023 | D11: =D22/76.6% -> 0.21148825 | E11: =H22/76.6% -> 0.22845953 | G11: =G22/76.6% -> 0.011749347 | H11: =I22/76.6% -> 0.010443864 | I11: =J22/76.6% -> 0.0091383812 | J11: =K22/76.6% -> 0.014360313 | K11: =L22/76.6% -> 0 | L11: =M22/76.6% -> 0 | M11: =N22/76.6% -> 0.01305483 | N11: =SUM(F11:M11) -> 0.058746736 | O11: =SUM(B11:M11) -> 1
A12: Omar Maluk 30/11 | B12: =B23/83.7% -> 0.28172043 | C12: =C23/83.7% -> 0.10621266 | D12: =D23/83.7% -> 0.073237754 | E12: =H23/83.7% -> 0.38016726 | F12: =F23/83.7% -> 0.021505376 | G12: =G23/83.7% -> 0.02962963 | H12: =I23/83.7% -> 0.016845878 | I12: =J23/83.7% -> 0.010752688 | J12: =K23/83.7% -> 0.028195938 | K12: =L23/83.7% -> 0 | L12: =M23/83.7% -> 0.015531661 | M12: =N23/83.7% -> 0.036678614 | N12: =SUM(F12:M12) -> 0.15913978 | O12: =SUM(B12:M12) -> 1.0004779
A13: Informe Confidencial 24/11 a 27/11 | B13: =B24/67% -> 0.29850746 | C13: =C24/67% -> 0.25373134 | D13: =D24/67% -> 0.17910448 | E13: =H24/67% -> 0.17910448 | F13: =F24/67% -> 0.029850746 | G13: =G24/67% -> 0 | H13: =I24/67% -> 0.014925373 | I13: =J24/67% -> 0 | J13: =K24/67% -> 0.014925373 | K13: =L24/67% -> 0 | L13: =M24/67% -> 0 | M13: =N24/67% -> 0.029850746 | N13: =SUM(F13:M13) -> 0.089552239 | O13: =SUM(B13:M13) -> 1
A14: Cedatos 15/11 | B14: =B25/44.5% -> 0.2494382 | C14: =C25/44.5% -> 0.40674157 | D14: =D25/44.5% -> 0.13932584 | E14: =H25/44.5% -> 0.16404494 | F14: =F25/44.5% -> 0.008988764 | G14: =G25/44.5% -> 0.004494382 | H14: =I25/44.5% -> 0.006741573 | I14: =J25/44.5% -> 0.002247191 | J14: =K25/44.5% -> 0.011235955 | K14: =L25/44.5% -> 0.002247191 | L14: =M25/44.5% -> 0.004494382 | M14: =N25/44.5% -> 0 | N14: =SUM(F14:M14) -> 0.040449438 | O14: =SUM(B14:M14) -> 1
A15: Promedio | B15: =AVERAGE(B4:B14) -> 0.31968177 | C15: =AVERAGE(C4:C14) -> 0.24162523 | D15: =AVERAGE(D4:D14) -> 0.1274587 | E15: =AVERAGE(E4:E14) -> 0.2215543 | F15: =AVERAGE(F4:F14) -> 0.018201819 | G15: =AVERAGE(G4:G14) -> 0.016088951 | H15: =AVERAGE(H4:H14) -> 0.020814164 | I15: =AVERAGE(I4:I14) -> 0.0073522333 | ... M15: =AVERAGE(M4:M14) -> 0.036930283
A18: Atlas Intel 23/12 a 29/12 | B18: 0.344 | C18: 0.267 | D18: 0.082 | F18: 0.01 | G18: 0.016 | H18: 0.116 | I18: 0.009 | J18: 0.004 | K18: 0.008 | L18: 0.001 | M18: 0.002 | N18: 0.036 | O18: 0.035 | Q18: 0.07
A19: Estrategia Consultores al 23/12 | B19: 0.223 | C19: 0.202 | D19: 0.174 | F19: 0.027 | I19: 0.021 | J19: 0.025 | K19: 0.043 | L19: 0.012 | N19: 0.098 | P19: 0.089 | Q19: 0.086
A20: Eureknow 14/12 a 22/12 | B20: 0.208 | C20: 0.2 | D20: 0.091 | F20: 0.041 | H20: 0.237 | K20: 0.044 | L20: 0.032 | N20: 0.065 | O20: 0.082
A21: Clima Social 12/12 a 15/12 | B21: 0.233 | C21: 0.139 | D21: 0.128 | F21: 0.013 | G21: 0.03 | H21: 0.108 | I21: 0.026 | J21: 0.012 | K21: 0.024 | L21: 0.012 | M21: 0.007 | N21: 0.052 | O21: 0.018 | P21: 0.068 | Q21: 0.131
A22: Celag 25/11 a 13/12 | B22: 0.28 | C22: 0.104 | D22: 0.162 | G22: 0.009 | H22: 0.175 | I22: 0.008 | J22: 0.007 | K22: 0.011 | N22: 0.01 | O22: 0.103 | Q22: 0.131
A23: Omar Maluk 30/11 | B23: 0.2358 | C23: 0.0889 | D23: 0.0613 | F23: 0.018 | G23: 0.0248 | H23: 0.3182 | I23: 0.0141 | J23: 0.009 | K23: 0.0236 | M23: 0.013 | N23: 0.0307 | O23: 0.0598 | P23: 0.1027
A24: Informe Confidencial 24/11 a 27/11 | B24: 0.2 | C24: 0.17 | D24: 0.12 | F24: 0.02 | H24: 0.12 | I24: 0.01 | K24: 0.01 | N24: 0.02 | P24: 0.27 | Q24: 0.06
A25: Cedatos 15/11 | B25: 0.111 | C25: 0.181 | D25: 0.062 | F25: 0.004 | G25: 0.002 | H25: 0.073 | I25: 0.003 | J25: 0.001 | K25: 0.005 | L25: 0.001 | M25: 0.002 | O25: 0.034 | P25: 0.286 | Q25: 0.235
A26: Clima Social 8/11 a 11/11 | B26: 0.23 | C26: 0.2 | D26: 0.129 | F26: 0.008 | G26: 0.026 | I26: 0.039 | J26: 0.017 | K26: 0.024 | L26: 0.01 | M26: 0.007 | N26: 0.022 | O26: 0.035 | P26: 0.112 | Q26: 0.139
A27: Informe Confidencial 6/11 a 9/11 | B27: 0.216 | C27: 0.17 | D27: 0.135 | F27: 0.016 | G27: 0.003 | I27: 0.012 | J27: 0.004 | K27: 0.004 | L27: 0.017 | M27: 0.002 | N27: 0.002 | O27: 0.151 | P27: 0.266 | Q27: 0.001
A28: Big Data 9/11 | B28: 0.354 | C28: 0.296 | D28: 0.094 | N28: 0.256
A29: Comunicaliza octubre | B29: 0.193 | C29: 0.177 | D29: 0.184 | G29: 0.032 | I29: 0.017 | K29: 0.016 | N29: 0.051 | P29: 0.164 | Q29: 0.166
A30: Cedatos 16/10 | B30: 0.197 | C30: 0.261 | D30: 0.131 | F30: 0.01 | G30: 0.01 | I30: 0.01 | J30: 0.01 | K30: 0.01 | L30: 0.01 | M30: 0.01 | O30: 0.088 | P30: 0.249
A31: Omar Maluk octubre | B31: 0.308 | C31: 0.238 | D31: 0.088 | F31: 0.028 | G31: 0.008 | I31: 0.022 | J31: 0.022 | K31: 0.024 | M31: 0.011 | N31: 0.021 | Q31: 0.231
A32: Omar Simón octubre | B32: 0.249 | C32: 0.111 | D32: 0.153 | F32: 0.011 | G32: 0.018 | I32: 0.02 | J32: 0.002 | L32: 0.019 | M32: 0.005 | N32: 0.037 | O32: 0.068 | P32: 0.213 | Q32: 0.095
A33: Clima Social 30/9 a 4/10 | B33: 0.186 | C33: 0.215 | D33: 0.107 | F33: 0.017 | G33: 0.046 | I33: 0.03 | J33: 0.039 | K33: 0.017 | L33: 0.017 | M33: 0.018 | N33: 0.006 | O33: 0.021 | P33: 0.12 | Q33: 0.161
A34: Pulso Ciudadano 15/9 a 18/9 | B34: 0.2105 | C34: 0.1912 | D34: 0.0617 | F34: 0.0602 | G34: 0.018 | I34: 0.0188 | J34: 0.0406 | K34: 0.0432 | M34: 0.0097 | N34: 0.025 | Q34: 0.322
A35: Cedatos 10/9 a 14/9 | B35: 0.123 | C35: 0.163 | D35: 0.055 | F35: 0.006 | G35: 0.008 | I35: 0.007 | K35: 0.005 | L35: 0.005 | M35: 0.005 | N35: 0.027 | O35: 0.006 | P35: 0.272 | Q35: 0.318
A36: Atlas Intel 8/9 a 14/9 | B36: 0.459 | C36: 0.32 | D36: 0.043 | F36: 0.011 | G36: 0.002 | I36: 0.003 | J36: 0.003 | K36: 0.009 | L36: 0.002 | M36: 0.009 | N36: 0.032 | O36: 0.061 | Q36: 0.045
A37: Eureknow 26/8 a 6/9 | B37: 0.22 | C37: 0.231 | D37: 0.205 | F37: 0.099 | K37: 0.066 | N37: 0.107 | O37: 0.072
B40: PROMEDIO | C40: Click Report Enero 2021 | D40: Atlas Intel 23/12 a 29/12 | E40: Mercanalisis CON NOBOA 15/12 a 23/12 | F40: Omar Maluk 7/12 a 23/12 | G40: Perfiles de Opinión CON NOBOA 12/2020 | H40: Eureknow 14/12 a 22/12 | I40: Clima Social 12/12 a 15/12 | J40: Celag 25/11 a 13/12 | K40: Omar Maluk 30/11 | L40: Informe Confidencial 24/11 a 27/11 | M40: Cedatos 15/11
A41: Andrés Arauz | B41: =AVERAGE(C41:M41) -> 0.30039665 | C41: 0.29926043 | D41: 0.38435754 | E41: 0.27118644 | F41: 0.28809152 | G41: 0.34211292 | H41: 0.22657952 | I41: 0.29757344 | J41: 0.36553525 | K41: 0.28172043 | L41: 0.29850746 | M41: 0.2494382
A42: Guillermo Lasso | B42: =AVERAGE(C42:M42) -> 0.22052156 | C42: 0.24841521 | D42: 0.29832402 | E42: 0.25423729 | F42: 0.14807592 | G42: 0.17884168 | H42: 0.21786492 | I42: 0.17752235 | J42: 0.13577023 | K42: 0.10621266 | L42: 0.25373134 | M42: 0.40674157
A43: Yaku Pérez | B43: =AVERAGE(C43:M43) -> 0.12907812 | C43: 0.12625462 | D43: 0.091620112 | E43: 0.10169492 | F43: 0.090613625 | G43: 0.14391735 | H43: 0.09912854 | I43: 0.16347382 | J43: 0.21148825 | K43: 0.073237754 | L43: 0.17910448 | M43: 0.13932584
A44: Álvaro Noboa | B44: =AVERAGE(C44:M44) -> 0.22446228 | C44: 0.25290544 | D44: 0.12960894 | E44: 0.11864407 | F44: 0.37441498 | G44: 0.24563446 | H44: 0.25816993 | I44: 0.13793103 | J44: 0.22845953 | K44: 0.38016726 | L44: 0.17910448 | M44: 0.16404494
...
